Workbook

Sheet (A) Introduction
B2: RELT — Register of Participants
B3: Last updated (date):
B4: Last updated by:
B6: Purpose
B7: This workbook stores information about RELT participants — tutors and the students they support — and is the central record the team uses to admit applicants, pair students with tutors, track tutoring delivery, and capture feedback and outcomes over time. It is designed to be maintained by many team members and to hold the program’s data for years.
B9: How to use this Register
B10: • Enter participant data only on "(B) Register of Participants". Coded fields use drop-downs — pick a value rather than free-typing.
B11: • Hover any column heading on (B) for a note explaining what the column is for and what to enter.
B12: • The grey "(H) HELPER COLUMNS" are formula-generated for the dashboard and Pairing Engine. Do not edit them.
B13: • The "Validation Flags" column auto-flags impossible combinations. Resolve any flagged row.
B15: Protecting the formatting when data is added
B16: • The (B) and (C) data ranges are Excel Tables. Microsoft Forms data arrives via Power Automate using "Add a row into a table", which writes values only and inherits the table’s formatting and column formulas automatically — so the flow never disturbs the styling.
... B33: Status taxonomy
B34: Code | C34: Label | D34: Explanation
B35: ERR-TST | C35: Error – Test | D35: Test entries to be discarded.
B36: ERR-DUP | C36: Error – Duplication | D36: Duplicate entries to be discarded.
B37: ERR-OTH | C37: Error – Other | D37: Errors of any other kind.
B38: NADM-UNP | C38: Not Admitted – Unprocessed | D38: To be processed.
B39: NADM-REJ-UNRES | C39: Not Admitted – Rejected (Unresponsive) | D39: Application made but contact could not be established.
B40: NADM-REJ-UNSUIT | C40: Not Admitted – Rejected (Unsuitable) | D40: Application made but unsuitable for any reason.
B41: ADM-ACT-UNMAT | C41: Admitted – Active – Unmatched | D41: To be paired.
B42: ADM-ACT-MAT-CNE | C42: Admitted – Active – Matched (Capacity Not Exhausted) | D42: Paired, with capacity for further pairings (tutors only).
B43: ADM-ACT-MAT-CE | C43: Admitted – Active – Matched (Capacity Exhausted) | D43: Paired, no remaining capacity. Students are always recorded here once paired.
B44: ADM-INACT-M&T | C44: Admitted – Inactive – Matched & Tutored | D44: Admitted and tutored but no longer active.
B45: ADM-INACT-NOM&T | C45: Admitted – Inactive – Has Not Tutored | D45: Admitted, has never tutored, and has become inactive.
B47: Capacity note: a tutor with room is ADM-ACT-MAT-CNE; a tutor at capacity is ADM-ACT-MAT-CE. A Student, once paired, is always ADM-ACT-MAT-CE; a Student recorded as CNE is flagged invalid.
B49: Data dictionary — (B) Register of Participants
B50: Group | C50: Column | D50: Notes
B51: (A) BASIC INFORMATION | C51: Unique ID | D51: Primary key. Never reuse.
B52: (A) BASIC INFORMATION | C52: Full Name | D52: —
B53: (A) BASIC INFORMATION | C53: Email Address | D53: —
B54: (A) BASIC INFORMATION | C54: Phone Number | D54: —
B55: (A) BASIC INFORMATION | C55: Emergency Contact Name | D55: Person to contact in an emergency involving the participant.
B56: (A) BASIC INFORMATION | C56: Emergency Contact Phone | D56: Emergency contact’s phone number.
B57: (A) BASIC INFORMATION | C57: Emergency Contact Relationship | D57: Emergency contact’s relationship to the participant.
B58: (A) BASIC INFORMATION | C58: Role | D58: Tutor or Student.
B59: (A) BASIC INFORMATION | C59: Application Date | D59: —
B60: (B) STATUS & ENROLMENT | C60: Status (code) | D60: Coded status (drop-down).
B61: (B) STATUS & ENROLMENT | C61: Status (plain English) | D61: Auto-translated from the code.
... B164: (H) HELPER COLUMNS (auto — | C164: CombinedAvailability | D164: —

Sheet (B) Register of Participants
A1: (A) BASIC INFORMATION | J1: (B) STATUS & ENROLMENT | W1: (C) PAIRING – DELIVERY | AG1: (D) PAIRING – SUBSTANTIVE | AX1: (E) VETTING | BL1: (F) GENERAL | BO1: (G) PAIRING HISTORY (record on tutor row; up to 5 over lifecycle) | CS1: (H) HELPER COLUMNS (auto — do not edit)
A2: Unique ID | B2: Full Name | C2: Email Address | D2: Phone Number | E2: Emergency Contact Name | F2: Emergency Contact Phone | G2: Emergency Contact Relationship | H2: Role | I2: Application Date | J2: Status (code) | K2: Status (plain English) | L2: Blacklisted | M2: Start Date | N2: End Date | O2: Student Number Capacity | P2: Current Pairings (count) | Q2: Total Pairings (historical) | R2: Current Pairing(s) | S2: Questionnaire and First Lesson Plan | T2: Current Session Location | U2: Current Session Time | V2: Date of Last Check In | W2: Timezone | X2: Availability – Monday (AEST) | Y2: Availability – Tuesday (AEST) | Z2: Availability – Wednesday (AEST) | AA2: Availability – Thursday (AEST) | AB2: Availability – Friday (AEST) | AC2: Availability – Saturday (AEST) | AD2: Availability – Sunday (AEST) | AE2: Mode | AF2: Technology Access | AG2: Country of Residence | AH2: State/Territory | AI2: Suburb | AJ2: Postcode | AK2: Date of Birth | AL2: Gender | AM2: Same-Gender Pairing Required (opt-in) | AN2: English Level (CEFR) | AO2: Qualitative Assessment | AP2: National Background | AQ2: Ethnic Background | AR2: Linguistic Background | AS2: Religious Background | AT2: Job / Study Category | AU2: Current Profession or Study | AV2: Intended Profession or Study | AW2: Hobbies and Interests | AX2: Refugee / Asylum Seeker Assessment | AY2: Interview Conducted | AZ2: Reference Check Conducted | BA2: Referee Name | BB2: Referee Relationship | BC2: Referee Contact | BD2: WWCC Provided | BE2: WWCC Number | BF2: WWCC Expiry | BG2: WWCC Confirmed | BH2: Approved to Tutor | BI2: Pathway to the Program | BJ2: Assessor | BK2: Matcher | BL2: General Comments | BM2: Matching Comments | BN2: Validation Flags | BO2: P1 Pairing ID | BP2: P1 Pairing Name | BQ2: P1 Start | BR2: P1 End | BS2: P1 Weekly Hours | BT2: P1 Recorded By | BU2: P2 Pairing ID | BV2: P2 Pairing Name | BW2: P2 Start | BX2: P2 End | BY2: P2 Weekly Hours | BZ2: P2 Recorded By | CA2: P3 Pairing ID | CB2: P3 Pairing Name | CC2: P3 Start | CD2: P3 End | CE2: P3 Weekly Hours | CF2: P3 Recorded By | CG2: P4 Pairing ID | CH2: P4 Pairing Name | CI2: P4 Start | CJ2: P4 End | CK2: P4 Weekly Hours | CL2: P4 Recorded By | CM2: P5 Pairing ID | CN2: P5 Pairing Name | CO2: P5 Start | CP2: P5 End | CQ2: P5 Weekly Hours | CR2: P5 Recorded By | CS2: IsApplicant | CT2: IsAdmitted | CU2: IsMatched | CV2: LeadTimesDays | CW2: DaysWaiting | CX2: MonthText | CY2: Age | CZ2: AgeBand | DA2: Current Weekly Hours | DB2: Total Hours To Date | DC2: DayAvailabilityMon | DD2: DayAvailabilityTue | DE2: DayAvailabilityWed | DF2: DayAvailabilityThu | DG2: DayAvailabilityFri | DH2: DayAvailabilitySat | DI2: DayAvailabilitySun | DJ2: CombinedAvailability
A3: T-O-00001 | B3: Aisha Yusuf | C3: aisha.yusuf1@example.com | D3: +61 451 687 665 | E3: Nadia King | F3: +61 473 484 248 | G3: Adult Child | H3: Tutor | I3: 45302 | J3: ADM-ACT-UNMAT | K3: =IFERROR(VLOOKUP(J3,'(A) Introduction'!$B$35:$C$45,2,FALSE),"") | L3: No | O3: 2 | P3: =IF($H3="Tutor",((BQ3<>"")*(BR3=""))+((BW3<>"")*(BX3=""))+((CC3<>"")*(CD3=""))+((CI3<>"")*(CJ3=""))+((CO3<>"")*(CP3="")),SUMPRODUCT(--($BO$3:$BO$202=$A3),--($BR$3:$BR$202=""))+SUMPRODUCT(--($BU$3:$BU$202=$A3),--($BX$3:$BX$202=""))+SUMPRODUCT(--($CA$3:$CA$202=$A3),--($CD$3:$CD$202=""))+SUMPRODUCT(--($CG$3:$CG$202=$A3),--($CJ$3:$CJ$202=""))+SUMPRODUCT(--($CM$3:$CM$202=$A3),--($CP$3:$CP$202=""))) | Q3: =IF($H3="Tutor",(BQ3<>"")+(BW3<>"")+(CC3<>"")+(CI3<>"")+(CO3<>""),SUMPRODUCT(--($BO$3:$BO$202=$A3))+SUMPRODUCT(--($BU$3:$BU$202=$A3))+SUMPRODUCT(--($CA$3:$CA$202=$A3))+SUMPRODUCT(--($CG$3:$CG$202=$A3))+SUMPRODUCT(--($CM$3:$CM$202=$A3))) | R3: =IF($H3="Tutor",TRIM(IF(AND(BQ3<>"",BR3=""),BP3&"; ","")&IF(AND(BW3<>"",BX3=""),BV3&"; ","")&IF(AND(CC3<>"",CD3=""),CB3&"; ","")&IF(AND(CI3<>"",CJ3=""),CH3&"; ","")&IF(AND(CO3<>"",CP3=""),CN3&"; ","")),IFERROR(INDEX($A$3:$B$202,(SUMPRODUCT(($BO$3:$BO$202=$A3)*($BR$3:$BR$202="")*ROW($BO$3:$BO$202))+SUMPRODUCT(($BU$3:$BU$202=$A3)*($BX$3:$BX$202="")*ROW($BU$3:$BU$202))+SUMPRODUCT(($CA$3:$CA$202=$A3)*($CD$3:$CD$202="")*ROW($CA$3:$CA$202))+SUMPRODUCT(($CG$3:$CG$202=$A3)*($CJ$3:$CJ$202="")*ROW($CG$3:$CG$202))+SUMPRODUCT(($CM$3:$CM$202=$A3)*($CP$3:$CP$202="")*ROW($CM$3:$CM$202)))-2,2),"")) | S3: Not Provided | V3: 45898 | W3: ACST (UTC+9:30) | X3: 6pm-9pm; | Y3: 6pm-9pm; | Z3: 12pm-3pm; | AA3: 12pm-3pm; | AB3: 6pm-9pm; | AC3: 6am-9am;9am-12pm; | AD3: NA; | AE3: Either | AF3: NA - Tutor | AG3: Australia | AH3: New South Wales | AI3: Auburn | AJ3: 2144 | AK3: 31722 | AL3: Female | AM3: NA | AN3: NA - Tutor | AO3: Moderate | AP3: Australia; Lebanon | AQ3: NA | AR3: English (C2) | AS3: Christian (Orthodox) | AT3: Business & Finance | AU3: Engineer | AV3: NA - Tutor | AW3: Gardening; Cooking; Walking | AX3: NA - Tutor | AY3: NA - Partner Organisation Verified | AZ3: Yes | BA3: Pedro Yusuf | BB3: Colleague | BC3: fatima.brown501@example.com | BD3: Pending | BG3: Yes | BH3: Adults Only | BI3: Supporting Asylum Seekers Sydney | BJ3: HERVIR Oliver | BK3: SHANAHAN Jack | BL3: Synthetic test record. | BN3: =TRIM(IF(AND($H3="Student",$J3="ADM-ACT-MAT-CNE"),"Invalid: Student cannot be CNE. ","")&IF(AND($H3="Student",ISNUMBER($O3)),"Check: capacity set for a Student. ","")&IF(AND(LEFT($J3,11)="ADM-ACT-MAT",$P3=0),"Check: matched status but 0 active pairings. ","")&IF(AND($H3="Tutor",ISNUMBER($O3),$P3>$O3),"Check: pairings exceed capacity. ","")&IF(AND($BH3="Everyone",NOT(AND($BD3="Yes",$BG3="Yes"))),"Check: approved to tutor children but WWCC not provided/confirmed. ","")&IF(AND($P3>0,NOT(AND(OR(LEFT($AY3,3)="Yes",LEFT($AY3,2)="NA"),OR(LEFT($AZ3,3)="Yes",LEFT($AZ3,2)="NA")))),"Matched but vetting incomplete (interview/reference). ","")&IF(COUNTIF($B$3:$B$600,$B3)>1,"Duplicate participant name. ","")) | CS3: =IF(LEFT($J3,3)="ERR",0,1) | CT3: =IF(LEFT($J3,3)="ADM",1,0) | CU3: =IF(OR($J3="ADM-ACT-MAT-CNE",$J3="ADM-ACT-MAT-CE",$J3="ADM-INACT-M&T"),1,0) | CV3: =IF(AND(CU3=1,ISNUMBER(M3),ISNUMBER(I3)),M3-I3,"") | CW3: =IF(ISNUMBER(I3),TODAY()-I3,"") | CX3: =IF(ISNUMBER(I3),DATE(YEAR(I3),MONTH(I3),1),"") | CY3: =IFERROR(DATEDIF(AK3,TODAY(),"y"),"") | CZ3: =IF(CY3="","",IF(CY3<28,"18-27",IF(CY3<38,"28-37",IF(CY3<48,"38-47",IF(CY3<58,"48-57",IF(CY3<68,"58-67",IF(CY3<78,"68-77","78+")))))) | DA3: =IF(AND(BQ3<>"",BR3=""),N(BS3),0)+IF(AND(BW3<>"",BX3=""),N(BY3),0)+IF(AND(CC3<>"",CD3=""),N(CE3),0)+IF(AND(CI3<>"",CJ3=""),N(CK3),0)+IF(AND(CO3<>"",CP3=""),N(CQ3),0) | DB3: =ROUND(IF(BQ3<>"",N(BS3)*MAX(0,((IF(BR3="",TODAY(),BR3))-BQ3)/7),0)+IF(BW3<>"",N(BY3)*MAX(0,((IF(BX3="",TODAY(),BX3))-BW3)/7),0)+IF(CC3<>"",N(CE3)*MAX(0,((IF(CD3="",TODAY(),CD3))-CC3)/7),0)+IF(CI3<>"",N(CK3)*MAX(0,((IF(CJ3="",TODAY(),CJ3))-CI3)/7),0)+IF(CO3<>"",N(CQ3)*MAX(0,((IF(CP3="",TODAY(),CP3))-CO3)/7),0),1) | DC3: =IF(OR(TRIM(X3)="",TRIM(X3)="NA;",TRIM(X3)="NA"),0,1) | DD3: =IF(OR(TRIM(Y3)="",TRIM(Y3)="NA;",TRIM(Y3)="NA"),0,1) | DE3: =IF(OR(TRIM(Z3)="",TRIM(Z3)="NA;",TRIM(Z3)="NA"),0,1) | DF3: =IF(OR(TRIM(AA3)="",TRIM(AA3)="NA;",TRIM(AA3)="NA"),0,1) | DG3: =IF(OR(TRIM(AB3)="",TRIM(AB3)="NA;",TRIM(AB3)="NA"),0,1) | DH3: =IF(OR(TRIM(AC3)="",TRIM(AC3)="NA;",TRIM(AC3)="NA"),0,1) | DI3: =IF(OR(TRIM(AD3)="",TRIM(AD3)="NA;",TRIM(AD3)="NA"),0,1) | DJ3: =TRIM(IF(DC3=1,"Mon ","")&IF(DD3=1,"Tue ","")&IF(DE3=1,"Wed ","")&IF(DF3=1,"Thu ","")&IF(DG3=1,"Fri ","")&IF(DH3=1,"Sat ","")&IF(DI3=1,"Sun ",""))
A4: T-O-00002 | B4: Sara Brown | C4: sara.brown2@example.com | D4: +61 459 884 746 | E4: Jose Schaffer | F4: +61 421 416 497 | G4: Adult Child | H4: Tutor | I4: 45321 | J4: ADM-ACT-MAT-CNE | K4: =IFERROR(VLOOKUP(J4,'(A) Introduction'!$B$35:$C$45,2,FALSE),"") | L4: No | O4: 2 | P4: =IF($H4="Tutor",((BQ4<>"")*(BR4=""))+((BW4<>"")*(BX4=""))+((CC4<>"")*(CD4=""))+((CI4<>"")*(CJ4=""))+((CO4<>"")*(CP4="")),SUMPRODUCT(--($BO$3:$BO$202=$A4),--($BR$3:$BR$202=""))+SUMPRODUCT(--($BU$3:$BU$202=$A4),--($BX$3:$BX$202=""))+SUMPRODUCT(--($CA$3:$CA$202=$A4),--($CD$3:$CD$202=""))+SUMPRODUCT(--($CG$3:$CG$202=$A4),--($CJ$3:$CJ$202=""))+SUMPRODUCT(--($CM$3:$CM$202=$A4),--($CP$3:$CP$202=""))) | Q4: =IF($H4="Tutor",(BQ4<>"")+(BW4<>"")+(CC4<>"")+(CI4<>"")+(CO4<>""),SUMPRODUCT(--($BO$3:$BO$202=$A4))+SUMPRODUCT(--($BU$3:$BU$202=$A4))+SUMPRODUCT(--($CA$3:$CA$202=$A4))+SUMPRODUCT(--($CG$3:$CG$202=$A4))+SUMPRODUCT(--($CM$3:$CM$202=$A4))) | R4: =IF($H4="Tutor",TRIM(IF(AND(BQ4<>"",BR4=""),BP4&"; ","")&IF(AND(BW4<>"",BX4=""),BV4&"; ","")&IF(AND(CC4<>"",CD4=""),CB4&"; ","")&IF(AND(CI4<>"",CJ4=""),CH4&"; ","")&IF(AND(CO4<>"",CP4=""),CN4&"; ","")),IFERROR(INDEX($A$3:$B$202,(SUMPRODUCT(($BO$3:$BO$202=$A4)*($BR$3:$BR$202="")*ROW($BO$3:$BO$202))+SUMPRODUCT(($BU$3:$BU$202=$A4)*($BX$3:$BX$202="")*ROW($BU$3:$BU$202))+SUMPRODUCT(($CA$3:$CA$202=$A4)*($CD$3:$CD$202="")*ROW($CA$3:$CA$202))+SUMPRODUCT(($CG$3:$CG$202=$A4)*($CJ$3:$CJ$202="")*ROW($CG$3:$CG$202))+SUMPRODUCT(($CM$3:$CM$202=$A4)*($CP$3:$CP$202="")*ROW($CM$3:$CM$202)))-2,2),"")) | S4: NA | V4: 45865 | W4: ACDT (UTC+10:30) | X4: 6pm-9pm; | Y4: NA; | Z4: 12pm-3pm;6pm-9pm; | AA4: 6am-9am;9am-12pm; | AB4: 6pm-9pm; | AC4: 12pm-3pm; | AD4: 12pm-3pm; | AE4: Online | AF4: NA - Tutor | AG4: Australia | AH4: New South Wales | AI4: Bankstown | AJ4: 2200 | AK4: 31433 | AL4: Male | AM4: NA | AN4: NA - Tutor | AO4: Moderate | AP4: Israel | AQ4: NA | AR4: English (C2) | AS4: Christian (Catholic) | AT4: Health & Medicine | AU4: Lawyer | AV4: NA - Tutor | AW4: Travel; Sport; Movies | AX4: NA - Tutor | AY4: Yes | AZ4: NA - Partner Organisation Verified | BA4: Carlos Cohen | BB4: Colleague | BC4: ahmad.slaytor502@example.com | BD4: Pending | BG4: Yes | BH4: Adults Only | BI4: Tasmania University (including the Law Society) | BJ4: SHANAHAN Jack | BK4: AGARWAL Akanksha | BL4: Synthetic test record. | BN4: =TRIM(IF(AND($H4="Student",$J4="ADM-ACT-MAT-CNE"),"Invalid: Student cannot be CNE. ","")&IF(AND($H4="Student",ISNUMBER($O4)),"Check: capacity set for a Student. ","")&IF(AND(LEFT($J4,11)="ADM-ACT-MAT",$P4=0),"Check: matched status but 0 active pairings. ","")&IF(AND($H4="Tutor",ISNUMBER($O4),$P4>$O4),"Check: pairings exceed capacity. ","")&IF(AND($BH4="Everyone",NOT(AND($BD4="Yes",$BG4="Yes"))),"Check: approved to tutor children but WWCC not provided/confirmed. ","")&IF(AND($P4>0,NOT(AND(OR(LEFT($AY4,3)="Yes",LEFT($AY4,2)="NA"),OR(LEFT($AZ4,3)="Yes",LEFT($AZ4,2)="NA")))),"Matched but vetting incomplete (interview/reference). ","")&IF(COUNTIF($B$3:$B$600,$B4)>1,"Duplicate participant name. ","")) | BO4: S-O-00023 | BP4: =IFERROR(VLOOKUP(BO4,$A:$B,2,FALSE),"") | BQ4: 45559 | BS4: 1.5 | BT4: NUICH Curtis | CS4: =IF(LEFT($J4,3)="ERR",0,1) | CT4: =IF(LEFT($J4,3)="ADM",1,0) | CU4: =IF(OR($J4="ADM-ACT-MAT-CNE",$J4="ADM-ACT-MAT-CE",$J4="ADM-INACT-M&T"),1,0) | CV4: =IF(AND(CU4=1,ISNUMBER(M4),ISNUMBER(I4)),M4-I4,"") | CW4: =IF(ISNUMBER(I4),TODAY()-I4,"") | CX4: =IF(ISNUMBER(I4),DATE(YEAR(I4),MONTH(I4),1),"") | CY4: =IFERROR(DATEDIF(AK4,TODAY(),"y"),"") | CZ4: =IF(CY4="","",IF(CY4<28,"18-27",IF(CY4<38,"28-37",IF(CY4<48,"38-47",IF(CY4<58,"48-57",IF(CY4<68,"58-67",IF(CY4<78,"68-77","78+")))))) | DA4: =IF(AND(BQ4<>"",BR4=""),N(BS4),0)+IF(AND(BW4<>"",BX4=""),N(BY4),0)+IF(AND(CC4<>"",CD4=""),N(CE4),0)+IF(AND(CI4<>"",CJ4=""),N(CK4),0)+IF(AND(CO4<>"",CP4=""),N(CQ4),0) | DB4: =ROUND(IF(BQ4<>"",N(BS4)*MAX(0,((IF(BR4="",TODAY(),BR4))-BQ4)/7),0)+IF(BW4<>"",N(BY4)*MAX(0,((IF(BX4="",TODAY(),BX4))-BW4)/7),0)+IF(CC4<>"",N(CE4)*MAX(0,((IF(CD4="",TODAY(),CD4))-CC4)/7),0)+IF(CI4<>"",N(CK4)*MAX(0,((IF(CJ4="",TODAY(),CJ4))-CI4)/7),0)+IF(CO4<>"",N(CQ4)*MAX(0,((IF(CP4="",TODAY(),CP4))-CO4)/7),0),1) | DC4: =IF(OR(TRIM(X4)="",TRIM(X4)="NA;",TRIM(X4)="NA"),0,1) | DD4: =IF(OR(TRIM(Y4)="",TRIM(Y4)="NA;",TRIM(Y4)="NA"),0,1) | DE4: =IF(OR(TRIM(Z4)="",TRIM(Z4)="NA;",TRIM(Z4)="NA"),0,1) | DF4: =IF(OR(TRIM(AA4)="",TRIM(AA4)="NA;",TRIM(AA4)="NA"),0,1) | DG4: =IF(OR(TRIM(AB4)="",TRIM(AB4)="NA;",TRIM(AB4)="NA"),0,1) | DH4: =IF(OR(TRIM(AC4)="",TRIM(AC4)="NA;",TRIM(AC4)="NA"),0,1) | DI4: =IF(OR(TRIM(AD4)="",TRIM(AD4)="NA;",TRIM(AD4)="NA"),0,1) | DJ4: =TRIM(IF(DC4=1,"Mon ","")&IF(DD4=1,"Tue ","")&IF(DE4=1,"Wed ","")&IF(DF4=1,"Thu ","")&IF(DG4=1,"Fri ","")&IF(DH4=1,"Sat ","")&IF(DI4=1,"Sun ",""))
A5: T-O-00003 | B5: Amir Slaytor | C5: amir.slaytor3@example.com | D5: +61 458 292 433 | E5: Grace Schaffer | F5: +61 474 608 040 | G5: Friend | H5: Tutor | I5: 45323 | J5: ADM-INACT-NOM&T | K5: =IFERROR(VLOOKUP(J5,'(A) Introduction'!$B$35:$C$45,2,FALSE),"") | L5: No | O5: 3 | P5: =IF($H5="Tutor",((BQ5<>"")*(BR5=""))+((BW5<>"")*(BX5=""))+((CC5<>"")*(CD5=""))+((CI5<>"")*(CJ5=""))+((CO5<>"")*(CP5="")),SUMPRODUCT(--($BO$3:$BO$202=$A5),--($BR$3:$BR$202=""))+SUMPRODUCT(--($BU$3:$BU$202=$A5),--($BX$3:$BX$202=""))+SUMPRODUCT(--($CA$3:$CA$202=$A5),--($CD$3:$CD$202=""))+SUMPRODUCT(--($CG$3:$CG$202=$A5),--($CJ$3:$CJ$202=""))+SUMPRODUCT(--($CM$3:$CM$202=$A5),--($CP$3:$CP$202=""))) | Q5: =IF($H5="Tutor",(BQ5<>"")+(BW5<>"")+(CC5<>"")+(CI5<>"")+(CO5<>""),SUMPRODUCT(--($BO$3:$BO$202=$A5))+SUMPRODUCT(--($BU$3:$BU$202=$A5))+SUMPRODUCT(--($CA$3:$CA$202=$A5))+SUMPRODUCT(--($CG$3:$CG$202=$A5))+SUMPRODUCT(--($CM$3:$CM$202=$A5))) | R5: =IF($H5="Tutor",TRIM(IF(AND(BQ5<>"",BR5=""),BP5&"; ","")&IF(AND(BW5<>"",BX5=""),BV5&"; ","")&IF(AND(CC5<>"",CD5=""),CB5&"; ","")&IF(AND(CI5<>"",CJ5=""),CH5&"; ","")&IF(AND(CO5<>"",CP5=""),CN5&"; ","")),IFERROR(INDEX($A$3:$B$202,(SUMPRODUCT(($BO$3:$BO$202=$A5)*($BR$3:$BR$202="")*ROW($BO$3:$BO$202))+SUMPRODUCT(($BU$3:$BU$202=$A5)*($BX$3:$BX$202="")*ROW($BU$3:$BU$202))+SUMPRODUCT(($CA$3:$CA$202=$A5)*($CD$3:$CD$202="")*ROW($CA$3:$CA$202))+SUMPRODUCT(($CG$3:$CG$202=$A5)*($CJ$3:$CJ$202="")*ROW($CG$3:$CG$202))+SUMPRODUCT(($CM$3:$CM$202=$A5)*($CP$3:$CP$202="")*ROW($CM$3:$CM$202)))-2,2),"")) | S5: NA | V5: 45585 | W5: ACDT (UTC+10:30) | X5: 6pm-9pm; | Y5: 9am-12pm; | Z5: 12pm-3pm; | AA5: 3pm-6pm; | AB5: 12pm-3pm; | AC5: NA; | AD5: 9am-12pm;12pm-3pm;3pm-6pm; | AE5: Online | AF5: NA - Tutor | AG5: Australia | AH5: New South Wales | AI5: Doonside | AJ5: 2767 | AK5: 34901 | AL5: Male | AM5: NA | AN5: NA - Tutor | AO5: Low | AP5: Australia | AQ5: NA | AR5: English (C2) | AS5: Christian (Catholic) | AT5: Arts, Media & Design | AU5: Retail | AV5: NA - Tutor | AW5: Cooking; Reading; Music | AX5: NA - Tutor | AY5: Yes | AZ5: Yes | BA5: Jose Levi | BB5: Academic Referee | BC5: lina.ibrahim503@example.com | BD5: Pending | BG5: Yes | BH5: Adults Only | BI5: Kaldor Centre for International Refugee Law | BJ5: MCCRORIE John | BK5: CROCK Mary | BL5: Synthetic test record. | BN5: =TRIM(IF(AND($H5="Student",$J5="ADM-ACT-MAT-CNE"),"Invalid: Student cannot be CNE. ","")&IF(AND($H5="Student",ISNUMBER($O5)),"Check: capacity set for a Student. ","")&IF(AND(LEFT($J5,11)="ADM-ACT-MAT",$P5=0),"Check: matched status but 0 active pairings. ","")&IF(AND($H5="Tutor",ISNUMBER($O5),$P5>$O5),"Check: pairings exceed capacity. ","")&IF(AND($BH5="Everyone",NOT(AND($BD5="Yes",$BG5="Yes"))),"Check: approved to tutor children but WWCC not provided/confirmed. ","")&IF(AND($P5>0,NOT(AND(OR(LEFT($AY5,3)="Yes",LEFT($AY5,2)="NA"),OR(LEFT($AZ5,3)="Yes",LEFT($AZ5,2)="NA")))),"Matched but vetting incomplete (interview/reference). ","")&IF(COUNTIF($B$3:$B$600,$B5)>1,"Duplicate participant name. ","")) | CS5: =IF(LEFT($J5,3)="ERR",0,1) | CT5: =IF(LEFT($J5,3)="ADM",1,0) | CU5: =IF(OR($J5="ADM-ACT-MAT-CNE",$J5="ADM-ACT-MAT-CE",$J5="ADM-INACT-M&T"),1,0) | CV5: =IF(AND(CU5=1,ISNUMBER(M5),ISNUMBER(I5)),M5-I5,"") | CW5: =IF(ISNUMBER(I5),TODAY()-I5,"") | CX5: =IF(ISNUMBER(I5),DATE(YEAR(I5),MONTH(I5),1),"") | CY5: =IFERROR(DATEDIF(AK5,TODAY(),"y"),"") | CZ5: =IF(CY5="","",IF(CY5<28,"18-27",IF(CY5<38,"28-37",IF(CY5<48,"38-47",IF(CY5<58,"48-57",IF(CY5<68,"58-67",IF(CY5<78,"68-77","78+")))))) | DA5: =IF(AND(BQ5<>"",BR5=""),N(BS5),0)+IF(AND(BW5<>"",BX5=""),N(BY5),0)+IF(AND(CC5<>"",CD5=""),N(CE5),0)+IF(AND(CI5<>"",CJ5=""),N(CK5),0)+IF(AND(CO5<>"",CP5=""),N(CQ5),0) | DB5: =ROUND(IF(BQ5<>"",N(BS5)*MAX(0,((IF(BR5="",TODAY(),BR5))-BQ5)/7),0)+IF(BW5<>"",N(BY5)*MAX(0,((IF(BX5="",TODAY(),BX5))-BW5)/7),0)+IF(CC5<>"",N(CE5)*MAX(0,((IF(CD5="",TODAY(),CD5))-CC5)/7),0)+IF(CI5<>"",N(CK5)*MAX(0,((IF(CJ5="",TODAY(),CJ5))-CI5)/7),0)+IF(CO5<>"",N(CQ5)*MAX(0,((IF(CP5="",TODAY(),CP5))-CO5)/7),0),1) | DC5: =IF(OR(TRIM(X5)="",TRIM(X5)="NA;",TRIM(X5)="NA"),0,1) | DD5: =IF(OR(TRIM(Y5)="",TRIM(Y5)="NA;",TRIM(Y5)="NA"),0,1) | DE5: =IF(OR(TRIM(Z5)="",TRIM(Z5)="NA;",TRIM(Z5)="NA"),0,1) | DF5: =IF(OR(TRIM(AA5)="",TRIM(AA5)="NA;",TRIM(AA5)="NA"),0,1) | DG5: =IF(OR(TRIM(AB5)="",TRIM(AB5)="NA;",TRIM(AB5)="NA"),0,1) | DH5: =IF(OR(TRIM(AC5)="",TRIM(AC5)="NA;",TRIM(AC5)="NA"),0,1) | DI5: =IF(OR(TRIM(AD5)="",TRIM(AD5)="NA;",TRIM(AD5)="NA"),0,1) | DJ5: =TRIM(IF(DC5=1,"Mon ","")&IF(DD5=1,"Tue ","")&IF(DE5=1,"Wed ","")&IF(DF5=1,"Thu ","")&IF(DG5=1,"Fri ","")&IF(DH5=1,"Sat ","")&IF(DI5=1,"Sun ",""))
A6: T-O-00004 | B6: Hannah Marks | C6: hannah.marks4@example.com | D6: +61 433 405 134 | E6: Hannah Young | F6: +61 438 954 679 | G6: Spouse | H6: Tutor | I6: 45326 | J6: ADM-INACT-NOM&T | K6: =IFERROR(VLOOKUP(J6,'(A) Introduction'!$B$35:$C$45,2,FALSE),"") | L6: No | O6: 2 | P6: =IF($H6="Tutor",((BQ6<>"")*(BR6=""))+((BW6<>"")*(BX6=""))+((CC6<>"")*(CD6=""))+((CI6<>"")*(CJ6=""))+((CO6<>"")*(CP6="")),SUMPRODUCT(--($BO$3:$BO$202=$A6),--($BR$3:$BR$202=""))+SUMPRODUCT(--($BU$3:$BU$202=$A6),--($BX$3:$BX$202=""))+SUMPRODUCT(--($CA$3:$CA$202=$A6),--($CD$3:$CD$202=""))+SUMPRODUCT(--($CG$3:$CG$202=$A6),--($CJ$3:$CJ$202=""))+SUMPRODUCT(--($CM$3:$CM$202=$A6),--($CP$3:$CP$202=""))) | Q6: =IF($H6="Tutor",(BQ6<>"")+(BW6<>"")+(CC6<>"")+(CI6<>"")+(CO6<>""),SUMPRODUCT(--($BO$3:$BO$202=$A6))+SUMPRODUCT(--($BU$3:$BU$202=$A6))+SUMPRODUCT(--($CA$3:$CA$202=$A6))+SUMPRODUCT(--($CG$3:$CG$202=$A6))+SUMPRODUCT(--($CM$3:$CM$202=$A6))) | R6: =IF($H6="Tutor",TRIM(IF(AND(BQ6<>"",BR6=""),BP6&"; ","")&IF(AND(BW6<>"",BX6=""),BV6&"; ","")&IF(AND(CC6<>"",CD6=""),CB6&"; ","")&IF(AND(CI6<>"",CJ6=""),CH6&"; ","")&IF(AND(CO6<>"",CP6=""),CN6&"; ","")),IFERROR(INDEX($A$3:$B$202,(SUMPRODUCT(($BO$3:$BO$202=$A6)*($BR$3:$BR$202="")*ROW($BO$3:$BO$202))+SUMPRODUCT(($BU$3:$BU$202=$A6)*($BX$3:$BX$202="")*ROW($BU$3:$BU$202))+SUMPRODUCT(($CA$3:$CA$202=$A6)*($CD$3:$CD$202="")*ROW($CA$3:$CA$202))+SUMPRODUCT(($CG$3:$CG$202=$A6)*($CJ$3:$CJ$202="")*ROW($CG$3:$CG$202))+SUMPRODUCT(($CM$3:$CM$202=$A6)*($CP$3:$CP$202="")*ROW($CM$3:$CM$202)))-2,2),"")) | S6: Not Provided | V6: 45576 | W6: AEST (UTC+10) | X6: 6pm-9pm; | Y6: NA; | Z6: 6pm-9pm; | AA6: 6pm-9pm; | AB6: 6pm-9pm; | AC6: 9am-12pm;12pm-3pm;3pm-6pm; | AD6: 12pm-3pm; | AE6: Either | AF6: NA - Tutor | AG6: Australia | AH6: New South Wales | AI6: Eastlakes | AJ6: 2018 | AK6: 26992 | AL6: Female | AM6: NA | AN6: NA - Tutor | AO6: High | AP6: Australia | AQ6: NA | AR6: English (C2) | AS6: Buddhist | AT6: Health & Medicine | AU6: Nurse | AV6: NA - Tutor | AW6: Art; Photography; Travel | AX6: NA - Tutor | AY6: No | AZ6: No | BA6: Nadia Stanley | BB6: Colleague | BC6: fatima.young504@example.com | BD6: Pending | BG6: No | BH6: Adults Only | BI6: Tasmania University (including the Law Society) | BJ6: SHANAHAN Jack | BK6: AGARWAL Akanksha | BL6: Synthetic test record. | BN6: =TRIM(IF(AND($H6="Student",$J6="ADM-ACT-MAT-CNE"),"Invalid: Student cannot be CNE. ","")&IF(AND($H6="Student",ISNUMBER($O6)),"Check: capacity set for a Student. ","")&IF(AND(LEFT($J6,11)="ADM-ACT-MAT",$P6=0),"Check: matched status but 0 active pairings. ","")&IF(AND($H6="Tutor",ISNUMBER($O6),$P6>$O6),"Check: pairings exceed capacity. ","")&IF(AND($BH6="Everyone",NOT(AND($BD6="Yes",$BG6="Yes"))),"Check: approved to tutor children but WWCC not provided/confirmed. ","")&IF(AND($P6>0,NOT(AND(OR(LEFT($AY6,3)="Yes",LEFT($AY6,2)="NA"),OR(LEFT($AZ6,3)="Yes",LEFT($AZ6,2)="NA")))),"Matched but vetting incomplete (interview/reference). ","")&IF(COUNTIF($B$3:$B$600,$B6)>1,"Duplicate participant name. ","")) | CS6: =IF(LEFT($J6,3)="ERR",0,1) | CT6: =IF(LEFT($J6,3)="ADM",1,0) | CU6: =IF(OR($J6="ADM-ACT-MAT-CNE",$J6="ADM-ACT-MAT-CE",$J6="ADM-INACT-M&T"),1,0) | CV6: =IF(AND(CU6=1,ISNUMBER(M6),ISNUMBER(I6)),M6-I6,"") | CW6: =IF(ISNUMBER(I6),TODAY()-I6,"") | CX6: =IF(ISNUMBER(I6),DATE(YEAR(I6),MONTH(I6),1),"") | CY6: =IFERROR(DATEDIF(AK6,TODAY(),"y"),"") | CZ6: =IF(CY6="","",IF(CY6<28,"18-27",IF(CY6<38,"28-37",IF(CY6<48,"38-47",IF(CY6<58,"48-57",IF(CY6<68,"58-67",IF(CY6<78,"68-77","78+")))))) | DA6: =IF(AND(BQ6<>"",BR6=""),N(BS6),0)+IF(AND(BW6<>"",BX6=""),N(BY6),0)+IF(AND(CC6<>"",CD6=""),N(CE6),0)+IF(AND(CI6<>"",CJ6=""),N(CK6),0)+IF(AND(CO6<>"",CP6=""),N(CQ6),0) | DB6: =ROUND(IF(BQ6<>"",N(BS6)*MAX(0,((IF(BR6="",TODAY(),BR6))-BQ6)/7),0)+IF(BW6<>"",N(BY6)*MAX(0,((IF(BX6="",TODAY(),BX6))-BW6)/7),0)+IF(CC6<>"",N(CE6)*MAX(0,((IF(CD6="",TODAY(),CD6))-CC6)/7),0)+IF(CI6<>"",N(CK6)*MAX(0,((IF(CJ6="",TODAY(),CJ6))-CI6)/7),0)+IF(CO6<>"",N(CQ6)*MAX(0,((IF(CP6="",TODAY(),CP6))-CO6)/7),0),1) | DC6: =IF(OR(TRIM(X6)="",TRIM(X6)="NA;",TRIM(X6)="NA"),0,1) | DD6: =IF(OR(TRIM(Y6)="",TRIM(Y6)="NA;",TRIM(Y6)="NA"),0,1) | DE6: =IF(OR(TRIM(Z6)="",TRIM(Z6)="NA;",TRIM(Z6)="NA"),0,1) | DF6: =IF(OR(TRIM(AA6)="",TRIM(AA6)="NA;",TRIM(AA6)="NA"),0,1) | DG6: =IF(OR(TRIM(AB6)="",TRIM(AB6)="NA;",TRIM(AB6)="NA"),0,1) | DH6: =IF(OR(TRIM(AC6)="",TRIM(AC6)="NA;",TRIM(AC6)="NA"),0,1) | DI6: =IF(OR(TRIM(AD6)="",TRIM(AD6)="NA;",TRIM(AD6)="NA"),0,1) | DJ6: =TRIM(IF(DC6=1,"Mon ","")&IF(DD6=1,"Tue ","")&IF(DE6=1,"Wed ","")&IF(DF6=1,"Thu ","")&IF(DG6=1,"Fri ","")&IF(DH6=1,"Sat ","")&IF(DI6=1,"Sun ",""))
A7: T-O-00005 | B7: Sofia Ng | C7: sofia.ng5@example.com | D7: +61 477 215 734 | E7: Karim Wright | F7: +61 470 151 440 | G7: Parent | H7: Tutor | I7: 45328 | J7: ADM-ACT-MAT-CNE | K7: =IFERROR(VLOOKUP(J7,'(A) Introduction'!$B$35:$C$45,2,FALSE),"") | L7: No | O7: 3 | P7: =IF($H7="Tutor",((BQ7<>"")*(BR7=""))+((BW7<>"")*(BX7=""))+((CC7<>"")*(CD7=""))+((CI7<>"")*(CJ7=""))+((CO7<>"")*(CP7="")),SUMPRODUCT(--($BO$3:$BO$202=$A7),--($BR$3:$BR$202=""))+SUMPRODUCT(--($BU$3:$BU$202=$A7),--($BX$3:$BX$202=""))+SUMPRODUCT(--($CA$3:$CA$202=$A7),--($CD$3:$CD$202=""))+SUMPRODUCT(--($CG$3:$CG$202=$A7),--($CJ$3:$CJ$202=""))+SUMPRODUCT(--($CM$3:$CM$202=$A7),--($CP$3:$CP$202=""))) | Q7: =IF($H7="Tutor",(BQ7<>"")+(BW7<>"")+(CC7<>"")+(CI7<>"")+(CO7<>""),SUMPRODUCT(--($BO$3:$BO$202=$A7))+SUMPRODUCT(--($BU$3:$BU$202=$A7))+SUMPRODUCT(--($CA$3:$CA$202=$A7))+SUMPRODUCT(--($CG$3:$CG$202=$A7))+SUMPRODUCT(--($CM$3:$CM$202=$A7))) | R7: =IF($H7="Tutor",TRIM(IF(AND(BQ7<>"",BR7=""),BP7&"; ","")&IF(AND(BW7<>"",BX7=""),BV7&"; ","")&IF(AND(CC7<>"",CD7=""),CB7&"; ","")&IF(AND(CI7<>"",CJ7=""),CH7&"; ","")&IF(AND(CO7<>"",CP7=""),CN7&"; ","")),IFERROR(INDEX($A$3:$B$202,(SUMPRODUCT(($BO$3:$BO$202=$A7)*($BR$3:$BR$202="")*ROW($BO$3:$BO$202))+SUMPRODUCT(($BU$3:$BU$202=$A7)*($BX$3:$BX$202="")*ROW($BU$3:$BU$202))+SUMPRODUCT(($CA$3:$CA$202=$A7)*($CD$3:$CD$202="")*ROW($CA$3:$CA$202))+SUMPRODUCT(($CG$3:$CG$202=$A7)*($CJ$3:$CJ$202="")*ROW($CG$3:$CG$202))+SUMPRODUCT(($CM$3:$CM$202=$A7)*($CP$3:$CP$202="")*ROW($CM$3:$CM$202)))-2,2),"")) | S7: Provided | V7: 45761 | W7: ACDT (UTC+10:30) | X7: 3pm-6pm; | Y7: 9am-12pm;12pm-3pm;3pm-6pm; | Z7: 6pm-9pm; | AA7: 3pm-6pm; | AB7: NA; | AC7: 6pm-9pm; | AD7: 12pm-3pm;6pm-9pm; | AE7: In-Person | AF7: NA - Tutor | AG7: Australia | AH7: New South Wales | AI7: Auburn | AJ7: 2144 | AK7: 23369 | AL7: Female | AM7: NA | AN7: NA - Tutor | AO7: High | AP7: Australia | AQ7: NA | AR7: English (C2) | AS7: None | AT7: Childcare & Aged Care | AU7: Lawyer | AV7: NA - Tutor | AW7: Football; Cooking; Family | AX7: NA - Tutor | AY7: NA - RELT Member Verified | AZ7: Yes | BA7: Olha Bourne | BB7: Academic Referee | BC7: olha.yang505@example.com | BD7: Yes | BE7: WWC5747180V | BF7: 46136 | BG7: Yes | BH7: Adults Only | BI7: CareerSeekers | BJ7: SHANAHAN Jack | BK7: AGARWAL Akanksha | BL7: Synthetic test record. | BN7: =TRIM(IF(AND($H7="Student",$J7="ADM-ACT-MAT-CNE"),"Invalid: Student cannot be CNE. ","")&IF(AND($H7="Student",ISNUMBER($O7)),"Check: capacity set for a Student. ","")&IF(AND(LEFT($J7,11)="ADM-ACT-MAT",$P7=0),"Check: matched status but 0 active pairings. ","")&IF(AND($H7="Tutor",ISNUMBER($O7),$P7>$O7),"Check: pairings exceed capacity. ","")&IF(AND($BH7="Everyone",NOT(AND($BD7="Yes",$BG7="Yes"))),"Check: approved to tutor children but WWCC not provided/confirmed. ","")&IF(AND($P7>0,NOT(AND(OR(LEFT($AY7,3)="Yes",LEFT($AY7,2)="NA"),OR(LEFT($AZ7,3)="Yes",LEFT($AZ7,2)="NA")))),"Matched but vetting incomplete (interview/reference). ","")&IF(COUNTIF($B$3:$B$600,$B7)>1,"Duplicate participant name. ","")) | BO7: S-O-00022 | BP7: =IFERROR(VLOOKUP(BO7,$A:$B,2,FALSE),"") | BQ7: 45484 | BS7: 1.5 | BT7: KNIJNIK Marina | BU7: S-O-00047 | BV7: =IFERROR(VLOOKUP(BU7,$A:$B,2,FALSE),"") | BW7: 45721 | BY7: 1 | BZ7: THET Moh Moh | CS7: =IF(LEFT($J7,3)="ERR",0,1) | CT7: =IF(LEFT($J7,3)="ADM",1,0) | CU7: =IF(OR($J7="ADM-ACT-MAT-CNE",$J7="ADM-ACT-MAT-CE",$J7="ADM-INACT-M&T"),1,0) | CV7: =IF(AND(CU7=1,ISNUMBER(M7),ISNUMBER(I7)),M7-I7,"") | CW7: =IF(ISNUMBER(I7),TODAY()-I7,"") | CX7: =IF(ISNUMBER(I7),DATE(YEAR(I7),MONTH(I7),1),"") | CY7: =IFERROR(DATEDIF(AK7,TODAY(),"y"),"") | CZ7: =IF(CY7="","",IF(CY7<28,"18-27",IF(CY7<38,"28-37",IF(CY7<48,"38-47",IF(CY7<58,"48-57",IF(CY7<68,"58-67",IF(CY7<78,"68-77","78+")))))) | DA7: =IF(AND(BQ7<>"",BR7=""),N(BS7),0)+IF(AND(BW7<>"",BX7=""),N(BY7),0)+IF(AND(CC7<>"",CD7=""),N(CE7),0)+IF(AND(CI7<>"",CJ7=""),N(CK7),0)+IF(AND(CO7<>"",CP7=""),N(CQ7),0) | DB7: =ROUND(IF(BQ7<>"",N(BS7)*MAX(0,((IF(BR7="",TODAY(),BR7))-BQ7)/7),0)+IF(BW7<>"",N(BY7)*MAX(0,((IF(BX7="",TODAY(),BX7))-BW7)/7),0)+IF(CC7<>"",N(CE7)*MAX(0,((IF(CD7="",TODAY(),CD7))-CC7)/7),0)+IF(CI7<>"",N(CK7)*MAX(0,((IF(CJ7="",TODAY(),CJ7))-CI7)/7),0)+IF(CO7<>"",N(CQ7)*MAX(0,((IF(CP7="",TODAY(),CP7))-CO7)/7),0),1) | DC7: =IF(OR(TRIM(X7)="",TRIM(X7)="NA;",TRIM(X7)="NA"),0,1) | DD7: =IF(OR(TRIM(Y7)="",TRIM(Y7)="NA;",TRIM(Y7)="NA"),0,1) | DE7: =IF(OR(TRIM(Z7)="",TRIM(Z7)="NA;",TRIM(Z7)="NA"),0,1) | DF7: =IF(OR(TRIM(AA7)="",TRIM(AA7)="NA;",TRIM(AA7)="NA"),0,1) | DG7: =IF(OR(TRIM(AB7)="",TRIM(AB7)="NA;",TRIM(AB7)="NA"),0,1) | DH7: =IF(OR(TRIM(AC7)="",TRIM(AC7)="NA;",TRIM(AC7)="NA"),0,1) | DI7: =IF(OR(TRIM(AD7)="",TRIM(AD7)="NA;",TRIM(AD7)="NA"),0,1) | DJ7: =TRIM(IF(DC7=1,"Mon ","")&IF(DD7=1,"Tue ","")&IF(DE7=1,"Wed ","")&IF(DF7=1,"Thu ","")&IF(DG7=1,"Fri ","")&IF(DH7=1,"Sat ","")&IF(DI7=1,"Sun ",""))
A8: T-O-00006 | B8: Carlos Schaffer | C8: carlos.schaffer6@example.com | D8: +61 445 798 573 | E8: Sara Bourne | F8: +61 429 228 024 | G8: Caseworker | H8: Tutor | I8: 45328 | J8: ADM-ACT-MAT-CNE | K8: =IFERROR(VLOOKUP(J8,'(A) Introduction'!$B$35:$C$45,2,FALSE),"") | L8: No | O8: 3 | P8: =IF($H8="Tutor",((BQ8<>"")*(BR8=""))+((BW8<>"")*(BX8=""))+((CC8<>"")*(CD8=""))+((CI8<>"")*(CJ8=""))+((CO8<>"")*(CP8="")),SUMPRODUCT(--($BO$3:$BO$202=$A8),--($BR$3:$BR$202=""))+SUMPRODUCT(--($BU$3:$BU$202=$A8),--($BX$3:$BX$202=""))+SUMPRODUCT(--($CA$3:$CA$202=$A8),--($CD$3:$CD$202=""))+SUMPRODUCT(--($CG$3:$CG$202=$A8),--($CJ$3:$CJ$202=""))+SUMPRODUCT(--($CM$3:$CM$202=$A8),--($CP$3:$CP$202=""))) | Q8: =IF($H8="Tutor",(BQ8<>"")+(BW8<>"")+(CC8<>"")+(CI8<>"")+(CO8<>""),SUMPRODUCT(--($BO$3:$BO$202=$A8))+SUMPRODUCT(--($BU$3:$BU$202=$A8))+SUMPRODUCT(--($CA$3:$CA$202=$A8))+SUMPRODUCT(--($CG$3:$CG$202=$A8))+SUMPRODUCT(--($CM$3:$CM$202=$A8))) | R8: =IF($H8="Tutor",TRIM(IF(AND(BQ8<>"",BR8=""),BP8&"; ","")&IF(AND(BW8<>"",BX8=""),BV8&"; ","")&IF(AND(CC8<>"",CD8=""),CB8&"; ","")&IF(AND(CI8<>"",CJ8=""),CH8&"; ","")&IF(AND(CO8<>"",CP8=""),CN8&"; ","")),IFERROR(INDEX($A$3:$B$202,(SUMPRODUCT(($BO$3:$BO$202=$A8)*($BR$3:$BR$202="")*ROW($BO$3:$BO$202))+SUMPRODUCT(($BU$3:$BU$202=$A8)*($BX$3:$BX$202="")*ROW($BU$3:$BU$202))+SUMPRODUCT(($CA$3:$CA$202=$A8)*($CD$3:$CD$202="")*ROW($CA$3:$CA$202))+SUMPRODUCT(($CG$3:$CG$202=$A8)*($CJ$3:$CJ$202="")*ROW($CG$3:$CG$202))+SUMPRODUCT(($CM$3:$CM$202=$A8)*($CP$3:$CP$202="")*ROW($CM$3:$CM$202)))-2,2),"")) | S8: NA | V8: 45796 | W8: ACDT (UTC+10:30) | X8: 9am-12pm; | Y8: 12pm-3pm; | Z8: 9am-12pm; | AA8: 9am-12pm; | AB8: 12pm-3pm;6pm-9pm; | AC8: NA; | AD8: 9am-12pm; | AE8: Either | AF8: NA - Tutor | AG8: Australia | AH8: New South Wales | AI8: Canterbury | AJ8: 2193 | AK8: 37793 | AL8: Male | AM8: NA | AN8: NA - Tutor | AO8: Outstanding | AP8: Vietnam | AQ8: NA | AR8: Arabic (C2); Pashto (B2) | AS8: Christian (Orthodox) | AT8: Health & Medicine | AU8: Nurse | AV8: NA - Tutor | AW8: Gardening; Cooking; Walking | AX8: NA - Tutor | AY8: Yes | AZ8: NA - Partner Organisation Verified | BA8: Elena Cohen | BB8: Academic Referee | BC8: ibrahim.hassan506@example.com | BD8: Yes | BE8: WWC7398678E | BF8: 46839 | BG8: No | BH8: Adults Only | BI8: Kaldor Centre for International Refugee Law | BJ8: HERVIR Oliver | BK8: NUICH Curtis | BL8: Synthetic test record. | BN8: =TRIM(IF(AND($H8="Student",$J8="ADM-ACT-MAT-CNE"),"Invalid: Student cannot be CNE. ","")&IF(AND($H8="Student",ISNUMBER($O8)),"Check: capacity set for a Student. ","")&IF(AND(LEFT($J8,11)="ADM-ACT-MAT",$P8=0),"Check: matched status but 0 active pairings. ","")&IF(AND($H8="Tutor",ISNUMBER($O8),$P8>$O8),"Check: pairings exceed capacity. ","")&IF(AND($BH8="Everyone",NOT(AND($BD8="Yes",$BG8="Yes"))),"Check: approved to tutor children but WWCC not provided/confirmed. ","")&IF(AND($P8>0,NOT(AND(OR(LEFT($AY8,3)="Yes",LEFT($AY8,2)="NA"),OR(LEFT($AZ8,3)="Yes",LEFT($AZ8,2)="NA")))),"Matched but vetting incomplete (interview/reference). ","")&IF(COUNTIF($B$3:$B$600,$B8)>1,"Duplicate participant name. ","")) | BO8: S-O-00010 | BP8: =IFERROR(VLOOKUP(BO8,$A:$B,2,FALSE),"") | BQ8: 45497 | BS8: 1 | BT8: AGARWAL Akanksha | CS8: =IF(LEFT($J8,3)="ERR",0,1) | CT8: =IF(LEFT($J8,3)="ADM",1,0) | CU8: =IF(OR($J8="ADM-ACT-MAT-CNE",$J8="ADM-ACT-MAT-CE",$J8="ADM-INACT-M&T"),1,0) | CV8: =IF(AND(CU8=1,ISNUMBER(M8),ISNUMBER(I8)),M8-I8,"") | CW8: =IF(ISNUMBER(I8),TODAY()-I8,"") | CX8: =IF(ISNUMBER(I8),DATE(YEAR(I8),MONTH(I8),1),"") | CY8: =IFERROR(DATEDIF(AK8,TODAY(),"y"),"") | CZ8: =IF(CY8="","",IF(CY8<28,"18-27",IF(CY8<38,"28-37",IF(CY8<48,"38-47",IF(CY8<58,"48-57",IF(CY8<68,"58-67",IF(CY8<78,"68-77","78+")))))) | DA8: =IF(AND(BQ8<>"",BR8=""),N(BS8),0)+IF(AND(BW8<>"",BX8=""),N(BY8),0)+IF(AND(CC8<>"",CD8=""),N(CE8),0)+IF(AND(CI8<>"",CJ8=""),N(CK8),0)+IF(AND(CO8<>"",CP8=""),N(CQ8),0) | DB8: =ROUND(IF(BQ8<>"",N(BS8)*MAX(0,((IF(BR8="",TODAY(),BR8))-BQ8)/7),0)+IF(BW8<>"",N(BY8)*MAX(0,((IF(BX8="",TODAY(),BX8))-BW8)/7),0)+IF(CC8<>"",N(CE8)*MAX(0,((IF(CD8="",TODAY(),CD8))-CC8)/7),0)+IF(CI8<>"",N(CK8)*MAX(0,((IF(CJ8="",TODAY(),CJ8))-CI8)/7),0)+IF(CO8<>"",N(CQ8)*MAX(0,((IF(CP8="",TODAY(),CP8))-CO8)/7),0),1) | DC8: =IF(OR(TRIM(X8)="",TRIM(X8)="NA;",TRIM(X8)="NA"),0,1) | DD8: =IF(OR(TRIM(Y8)="",TRIM(Y8)="NA;",TRIM(Y8)="NA"),0,1) | DE8: =IF(OR(TRIM(Z8)="",TRIM(Z8)="NA;",TRIM(Z8)="NA"),0,1) | DF8: =IF(OR(TRIM(AA8)="",TRIM(AA8)="NA;",TRIM(AA8)="NA"),0,1) | DG8: =IF(OR(TRIM(AB8)="",TRIM(AB8)="NA;",TRIM(AB8)="NA"),0,1) | DH8: =IF(OR(TRIM(AC8)="",TRIM(AC8)="NA;",TRIM(AC8)="NA"),0,1) | DI8: =IF(OR(TRIM(AD8)="",TRIM(AD8)="NA;",TRIM(AD8)="NA"),0,1) | DJ8: =TRIM(IF(DC8=1,"Mon ","")&IF(DD8=1,"Tue ","")&IF(DE8=1,"Wed ","")&IF(DF8=1,"Thu ","")&IF(DG8=1,"Fri ","")&IF(DH8=1,"Sat ","")&IF(DI8=1,"Sun ",""))
A9: T-O-00007 | B9: Luke Ng | C9: luke.ng7@example.com | D9: +61 482 521 409 | E9: Chloe Yusuf | F9: +61 446 441 071 | G9: Caseworker | H9: Tutor | I9: 45340 | J9: ADM-ACT-UNMAT | K9: =IFERROR(VLOOKUP(J9,'(A) Introduction'!$B$35:$C$45,2,FALSE),"") | L9: No | O9: 3 | P9: =IF($H9="Tutor",((BQ9<>"")*(BR9=""))+((BW9<>"")*(BX9=""))+((CC9<>"")*(CD9=""))+((CI9<>"")*(CJ9=""))+((CO9<>"")*(CP9="")),SUMPRODUCT(--($BO$3:$BO$202=$A9),--($BR$3:$BR$202=""))+SUMPRODUCT(--($BU$3:$BU$202=$A9),--($BX$3:$BX$202=""))+SUMPRODUCT(--($CA$3:$CA$202=$A9),--($CD$3:$CD$202=""))+SUMPRODUCT(--($CG$3:$CG$202=$A9),--($CJ$3:$CJ$202=""))+SUMPRODUCT(--($CM$3:$CM$202=$A9),--($CP$3:$CP$202=""))) | Q9: =IF($H9="Tutor",(BQ9<>"")+(BW9<>"")+(CC9<>"")+(CI9<>"")+(CO9<>""),SUMPRODUCT(--($BO$3:$BO$202=$A9))+SUMPRODUCT(--($BU$3:$BU$202=$A9))+SUMPRODUCT(--($CA$3:$CA$202=$A9))+SUMPRODUCT(--($CG$3:$CG$202=$A9))+SUMPRODUCT(--($CM$3:$CM$202=$A9))) | R9: =IF($H9="Tutor",TRIM(IF(AND(BQ9<>"",BR9=""),BP9&"; ","")&IF(AND(BW9<>"",BX9=""),BV9&"; ","")&IF(AND(CC9<>"",CD9=""),CB9&"; ","")&IF(AND(CI9<>"",CJ9=""),CH9&"; ","")&IF(AND(CO9<>"",CP9=""),CN9&"; ","")),IFERROR(INDEX($A$3:$B$202,(SUMPRODUCT(($BO$3:$BO$202=$A9)*($BR$3:$BR$202="")*ROW($BO$3:$BO$202))+SUMPRODUCT(($BU$3:$BU$202=$A9)*($BX$3:$BX$202="")*ROW($BU$3:$BU$202))+SUMPRODUCT(($CA$3:$CA$202=$A9)*($CD$3:$CD$202="")*ROW($CA$3:$CA$202))+SUMPRODUCT(($CG$3:$CG$202=$A9)*($CJ$3:$CJ$202="")*ROW($CG$3:$CG$202))+SUMPRODUCT(($CM$3:$CM$202=$A9)*($CP$3:$CP$202="")*ROW($CM$3:$CM$202)))-2,2),"")) | S9: Not Provided | V9: 45725 | W9: AEST (UTC+10) | X9: 6pm-9pm; | Y9: 3pm-6pm; | Z9: 9am-12pm; | AA9: 3pm-6pm; | AB9: NA; | AC9: 6pm-9pm; | AD9: 12pm-3pm;6pm-9pm; | AE9: In-Person | AF9: NA - Tutor | AG9: Australia | AH9: New South Wales | AI9: Liverpool | AJ9: 2170 | AK9: 34583 | AL9: Male | AM9: NA | AN9: NA - Tutor | AO9: Outstanding | AP9: Egypt | AQ9: NA | AR9: Pashto (C2) | AS9: Christian | AT9: Labour, Administrative & Clerical | AU9: Aged Care Worker | AV9: NA - Tutor | AW9: Travel; Sport; Movies | AX9: NA - Tutor | AY9: NA - Partner Organisation Verified | AZ9: Yes | BA9: Reza Baker | BB9: Academic Referee | BC9: hannah.khan507@example.com | BD9: Pending | BG9: Yes | BH9: Adults Only | BI9: University of Sydney (including St. Paul's College) | BJ9: SHANAHAN Jack | BK9: THET Moh Moh | BL9: Synthetic test record. | BN9: =TRIM(IF(AND($H9="Student",$J9="ADM-ACT-MAT-CNE"),"Invalid: Student cannot be CNE. ","")&IF(AND($H9="Student",ISNUMBER($O9)),"Check: capacity set for a Student. ","")&IF(AND(LEFT($J9,11)="ADM-ACT-MAT",$P9=0),"Check: matched status but 0 active pairings. ","")&IF(AND($H9="Tutor",ISNUMBER($O9),$P9>$O9),"Check: pairings exceed capacity. ","")&IF(AND($BH9="Everyone",NOT(AND($BD9="Yes",$BG9="Yes"))),"Check: approved to tutor children but WWCC not provided/confirmed. ","")&IF(AND($P9>0,NOT(AND(OR(LEFT($AY9,3)="Yes",LEFT($AY9,2)="NA"),OR(LEFT($AZ9,3)="Yes",LEFT($AZ9,2)="NA")))),"Matched but vetting incomplete (interview/reference). ","")&IF(COUNTIF($B$3:$B$600,$B9)>1,"Duplicate participant name. ","")) | CS9: =IF(LEFT($J9,3)="ERR",0,1) | CT9: =IF(LEFT($J9,3)="ADM",1,0) | CU9: =IF(OR($J9="ADM-ACT-MAT-CNE",$J9="ADM-ACT-MAT-CE",$J9="ADM-INACT-M&T"),1,0) | CV9: =IF(AND(CU9=1,ISNUMBER(M9),ISNUMBER(I9)),M9-I9,"") | CW9: =IF(ISNUMBER(I9),TODAY()-I9,"") | CX9: =IF(ISNUMBER(I9),DATE(YEAR(I9),MONTH(I9),1),"") | CY9: =IFERROR(DATEDIF(AK9,TODAY(),"y"),"") | CZ9: =IF(CY9="","",IF(CY9<28,"18-27",IF(CY9<38,"28-37",IF(CY9<48,"38-47",IF(CY9<58,"48-57",IF(CY9<68,"58-67",IF(CY9<78,"68-77","78+")))))) | DA9: =IF(AND(BQ9<>"",BR9=""),N(BS9),0)+IF(AND(BW9<>"",BX9=""),N(BY9),0)+IF(AND(CC9<>"",CD9=""),N(CE9),0)+IF(AND(CI9<>"",CJ9=""),N(CK9),0)+IF(AND(CO9<>"",CP9=""),N(CQ9),0) | DB9: =ROUND(IF(BQ9<>"",N(BS9)*MAX(0,((IF(BR9="",TODAY(),BR9))-BQ9)/7),0)+IF(BW9<>"",N(BY9)*MAX(0,((IF(BX9="",TODAY(),BX9))-BW9)/7),0)+IF(CC9<>"",N(CE9)*MAX(0,((IF(CD9="",TODAY(),CD9))-CC9)/7),0)+IF(CI9<>"",N(CK9)*MAX(0,((IF(CJ9="",TODAY(),CJ9))-CI9)/7),0)+IF(CO9<>"",N(CQ9)*MAX(0,((IF(CP9="",TODAY(),CP9))-CO9)/7),0),1) | DC9: =IF(OR(TRIM(X9)="",TRIM(X9)="NA;",TRIM(X9)="NA"),0,1) | DD9: =IF(OR(TRIM(Y9)="",TRIM(Y9)="NA;",TRIM(Y9)="NA"),0,1) | DE9: =IF(OR(TRIM(Z9)="",TRIM(Z9)="NA;",TRIM(Z9)="NA"),0,1) | DF9: =IF(OR(TRIM(AA9)="",TRIM(AA9)="NA;",TRIM(AA9)="NA"),0,1) | DG9: =IF(OR(TRIM(AB9)="",TRIM(AB9)="NA;",TRIM(AB9)="NA"),0,1) | DH9: =IF(OR(TRIM(AC9)="",TRIM(AC9)="NA;",TRIM(AC9)="NA"),0,1) | DI9: =IF(OR(TRIM(AD9)="",TRIM(AD9)="NA;",TRIM(AD9)="NA"),0,1) | DJ9: =TRIM(IF(DC9=1,"Mon ","")&IF(DD9=1,"Tue ","")&IF(DE9=1,"Wed ","")&IF(DF9=1,"Thu ","")&IF(DG9=1,"Fri ","")&IF(DH9=1,"Sat ","")&IF(DI9=1,"Sun ",""))
A10: T-O-00008 | B10: Chloe Bourne | C10: chloe.bourne8@example.com | D10: +61 439 682 418 | E10: Sam Silva | F10: +61 484 086 290 | G10: Friend | H10: Tutor | I10: 45342 | J10: ADM-INACT-NOM&T | K10: =IFERROR(VLOOKUP(J10,'(A) Introduction'!$B$35:$C$45,2,FALSE),"") | L10: No | O10: 2 | P10: =IF($H10="Tutor",((BQ10<>"")*(BR10=""))+((BW10<>"")*(BX10=""))+((CC10<>"")*(CD10=""))+((CI10<>"")*(CJ10=""))+((CO10<>"")*(CP10="")),SUMPRODUCT(--($BO$3:$BO$202=$A10),--($BR$3:$BR$202=""))+SUMPRODUCT(--($BU$3:$BU$202=$A10),--($BX$3:$BX$202=""))+SUMPRODUCT(--($CA$3:$CA$202=$A10),--($CD$3:$CD$202=""))+SUMPRODUCT(--($CG$3:$CG$202=$A10),--($CJ$3:$CJ$202=""))+SUMPRODUCT(--($CM$3:$CM$202=$A10),--($CP$3:$CP$202=""))) | Q10: =IF($H10="Tutor",(BQ10<>"")+(BW10<>"")+(CC10<>"")+(CI10<>"")+(CO10<>""),SUMPRODUCT(--($BO$3:$BO$202=$A10))+SUMPRODUCT(--($BU$3:$BU$202=$A10))+SUMPRODUCT(--($CA$3:$CA$202=$A10))+SUMPRODUCT(--($CG$3:$CG$202=$A10))+SUMPRODUCT(--($CM$3:$CM$202=$A10))) | R10: =IF($H10="Tutor",TRIM(IF(AND(BQ10<>"",BR10=""),BP10&"; ","")&IF(AND(BW10<>"",BX10=""),BV10&"; ","")&IF(AND(CC10<>"",CD10=""),CB10&"; ","")&IF(AND(CI10<>"",CJ10=""),CH10&"; ","")&IF(AND(CO10<>"",CP10=""),CN10&"; ","")),IFERROR(INDEX($A$3:$B$202,(SUMPRODUCT(($BO$3:$BO$202=$A10)*($BR$3:$BR$202="")*ROW($BO$3:$BO$202))+SUMPRODUCT(($BU$3:$BU$202=$A10)*($BX$3:$BX$202="")*ROW($BU$3:$BU$202))+SUMPRODUCT(($CA$3:$CA$202=$A10)*($CD$3:$CD$202="")*ROW($CA$3:$CA$202))+SUMPRODUCT(($CG$3:$CG$202=$A10)*($CJ$3:$CJ$202="")*ROW($CG$3:$CG$202))+SUMPRODUCT(($CM$3:$CM$202=$A10)*($CP$3:$CP$202="")*ROW($CM$3:$CM$202)))-2,2),"")) | S10: Not Provided | V10: 45662 | W10: ACDT (UTC+10:30) | X10: 3pm-6pm; | Y10: 9am-12pm;12pm-3pm;3pm-6pm; | Z10: 9am-12pm; | AA10: 12pm-3pm; | AB10: 12pm-3pm;6pm-9pm; | AC10: 12pm-3pm;6pm-9pm; | AD10: 9am-12pm; | AE10: Either | AF10: NA - Tutor | AG10: Australia | AH10: Victoria | AI10: Dandenong | AJ10: 3175 | AK10: 31971 | AL10: Male | AM10: NA | AN10: NA - Tutor | AO10: Outstanding | AP10: Lebanon | AQ10: NA | AR10: English (C2) | AS10: Muslim | AT10: Health & Medicine | AU10: Accountant | AV10: NA - Tutor | AW10: Travel; Sport; Movies | AX10: NA - Tutor | AY10: NA - RELT Member Verified | AZ10: No | BA10: Hannah Baker | BB10: Academic Referee | BC10: jose.schaffer508@example.com | BD10: Yes | BE10: WWC5280939E | BF10: 46514 | BG10: Yes | BH10: Adults Only | BI10: Jesuit Refugee Service | BJ10: SHANAHAN Jack | BK10: NUICH Curtis | BL10: Synthetic test record. | BN10: =TRIM(IF(AND($H10="Student",$J10="ADM-ACT-MAT-CNE"),"Invalid: Student cannot be CNE. ","")&IF(AND($H10="Student",ISNUMBER($O10)),"Check: capacity set for a Student. ","")&IF(AND(LEFT($J10,11)="ADM-ACT-MAT",$P10=0),"Check: matched status but 0 active pairings. ","")&IF(AND($H10="Tutor",ISNUMBER($O10),$P10>$O10),"Check: pairings exceed capacity. ","")&IF(AND($BH10="Everyone",NOT(AND($BD10="Yes",$BG10="Yes"))),"Check: approved to tutor children but WWCC not provided/confirmed. ","")&IF(AND($P10>0,NOT(AND(OR(LEFT($AY10,3)="Yes",LEFT($AY10,2)="NA"),OR(LEFT($AZ10,3)="Yes",LEFT($AZ10,2)="NA")))),"Matched but vetting incomplete (interview/reference). ","")&IF(COUNTIF($B$3:$B$600,$B10)>1,"Duplicate participant name. ","")) | CS10: =IF(LEFT($J10,3)="ERR",0,1) | CT10: =IF(LEFT($J10,3)="ADM",1,0) | CU10: =IF(OR($J10="ADM-ACT-MAT-CNE",$J10="ADM-ACT-MAT-CE",$J10="ADM-INACT-M&T"),1,0) | CV10: =IF(AND(CU10=1,ISNUMBER(M10),ISNUMBER(I10)),M10-I10,"") | CW10: =IF(ISNUMBER(I10),TODAY()-I10,"") | CX10: =IF(ISNUMBER(I10),DATE(YEAR(I10),MONTH(I10),1),"") | CY10: =IFERROR(DATEDIF(AK10,TODAY(),"y"),"") | CZ10: =IF(CY10="","",IF(CY10<28,"18-27",IF(CY10<38,"28-37",IF(CY10<48,"38-47",IF(CY10<58,"48-57",IF(CY10<68,"58-67",IF(CY10<78,"68-77","78+")))))) | DA10: =IF(AND(BQ10<>"",BR10=""),N(BS10),0)+IF(AND(BW10<>"",BX10=""),N(BY10),0)+IF(AND(CC10<>"",CD10=""),N(CE10),0)+IF(AND(CI10<>"",CJ10=""),N(CK10),0)+IF(AND(CO10<>"",CP10=""),N(CQ10),0) | DB10: =ROUND(IF(BQ10<>"",N(BS10)*MAX(0,((IF(BR10="",TODAY(),BR10))-BQ10)/7),0)+IF(BW10<>"",N(BY10)*MAX(0,((IF(BX10="",TODAY(),BX10))-BW10)/7),0)+IF(CC10<>"",N(CE10)*MAX(0,((IF(CD10="",TODAY(),CD10))-CC10)/7),0)+IF(CI10<>"",N(CK10)*MAX(0,((IF(CJ10="",TODAY(),CJ10))-CI10)/7),0)+IF(CO10<>"",N(CQ10)*MAX(0,((IF(CP10="",TODAY(),CP10))-CO10)/7),0),1) | DC10: =IF(OR(TRIM(X10)="",TRIM(X10)="NA;",TRIM(X10)="NA"),0,1) | DD10: =IF(OR(TRIM(Y10)="",TRIM(Y10)="NA;",TRIM(Y10)="NA"),0,1) | DE10: =IF(OR(TRIM(Z10)="",TRIM(Z10)="NA;",TRIM(Z10)="NA"),0,1) | DF10: =IF(OR(TRIM(AA10)="",TRIM(AA10)="NA;",TRIM(AA10)="NA"),0,1) | DG10: =IF(OR(TRIM(AB10)="",TRIM(AB10)="NA;",TRIM(AB10)="NA"),0,1) | DH10: =IF(OR(TRIM(AC10)="",TRIM(AC10)="NA;",TRIM(AC10)="NA"),0,1) | DI10: =IF(OR(TRIM(AD10)="",TRIM(AD10)="NA;",TRIM(AD10)="NA"),0,1) | DJ10: =TRIM(IF(DC10=1,"Mon ","")&IF(DD10=1,"Tue ","")&IF(DE10=1,"Wed ","")&IF(DF10=1,"Thu ","")&IF(DG10=1,"Fri ","")&IF(DH10=1,"Sat ","")&IF(DI10=1,"Sun ",""))
A11: T-O-00009 | B11: Mark Bourne | C11: mark.bourne9@example.com | D11: +61 425 150 025 | E11: Daniel Green | F11: +61 440 972 773 | G11: Adult Child | H11: Tutor | I11: 45353 | J11: ADM-ACT-MAT-CE | K11: =IFERROR(VLOOKUP(J11,'(A) Introduction'!$B$35:$C$45,2,FALSE),"") | L11: No | O11: 2 | P11: =IF($H11="Tutor",((BQ11<>"")*(BR11=""))+((BW11<>"")*(BX11=""))+((CC11<>"")*(CD11=""))+((CI11<>"")*(CJ11=""))+((CO11<>"")*(CP11="")),SUMPRODUCT(--($BO$3:$BO$202=$A11),--($BR$3:$BR$202=""))+SUMPRODUCT(--($BU$3:$BU$202=$A11),--($BX$3:$BX$202=""))+SUMPRODUCT(--($CA$3:$CA$202=$A11),--($CD$3:$CD$202=""))+SUMPRODUCT(--($CG$3:$CG$202=$A11),--($CJ$3:$CJ$202=""))+SUMPRODUCT(--($CM$3:$CM$202=$A11),--($CP$3:$CP$202=""))) | Q11: =IF($H11="Tutor",(BQ11<>"")+(BW11<>"")+(CC11<>"")+(CI11<>"")+(CO11<>""),SUMPRODUCT(--($BO$3:$BO$202=$A11))+SUMPRODUCT(--($BU$3:$BU$202=$A11))+SUMPRODUCT(--($CA$3:$CA$202=$A11))+SUMPRODUCT(--($CG$3:$CG$202=$A11))+SUMPRODUCT(--($CM$3:$CM$202=$A11))) | R11: =IF($H11="Tutor",TRIM(IF(AND(BQ11<>"",BR11=""),BP11&"; ","")&IF(AND(BW11<>"",BX11=""),BV11&"; ","")&IF(AND(CC11<>"",CD11=""),CB11&"; ","")&IF(AND(CI11<>"",CJ11=""),CH11&"; ","")&IF(AND(CO11<>"",CP11=""),CN11&"; ","")),IFERROR(INDEX($A$3:$B$202,(SUMPRODUCT(($BO$3:$BO$202=$A11)*($BR$3:$BR$202="")*ROW($BO$3:$BO$202))+SUMPRODUCT(($BU$3:$BU$202=$A11)*($BX$3:$BX$202="")*ROW($BU$3:$BU$202))+SUMPRODUCT(($CA$3:$CA$202=$A11)*($CD$3:$CD$202="")*ROW($CA$3:$CA$202))+SUMPRODUCT(($CG$3:$CG$202=$A11)*($CJ$3:$CJ$202="")*ROW($CG$3:$CG$202))+SUMPRODUCT(($CM$3:$CM$202=$A11)*($CP$3:$CP$202="")*ROW($CM$3:$CM$202)))-2,2),"")) | S11: Provided | V11: 46139 | W11: AEDT (UTC+11) | X11: 6pm-9pm; | Y11: 6pm-9pm; | Z11: 12pm-3pm;6pm-9pm; | AA11: 12pm-3pm; | AB11: 12pm-3pm;6pm-9pm; | AC11: 6pm-9pm; | AD11: 12pm-3pm;6pm-9pm; | AE11: Online | AF11: NA - Tutor | AG11: Australia | AH11: New South Wales | AI11: Eastlakes | AJ11: 2018 | AK11: 25064 | AL11: Other | AM11: NA | AN11: NA - Tutor | AO11: Low | AP11: Australia | AQ11: NA | AR11: English (C2) | AS11: Christian (Orthodox) | AT11: Childcare & Aged Care | AU11: Retail | AV11: NA - Tutor | AW11: Art; Photography; Travel | AX11: NA - Tutor | AY11: Yes | AZ11: Yes | BA11: Tom Lee | BB11: Friend | BC11: daniel.smith509@example.com | BD11: Yes | BE11: WWC7692721E | BF11: 46065 | BG11: Yes | BH11: Adults Only | BI11: STARTTS | BJ11: THET Moh Moh | BK11: SHANAHAN Jack | BL11: Synthetic test record. | BN11: =TRIM(IF(AND($H11="Student",$J11="ADM-ACT-MAT-CNE"),"Invalid: Student cannot be CNE. ","")&IF(AND($H11="Student",ISNUMBER($O11)),"Check: capacity set for a Student. ","")&IF(AND(LEFT($J11,11)="ADM-ACT-MAT",$P11=0),"Check: matched status but 0 active pairings. ","")&IF(AND($H11="Tutor",ISNUMBER($O11),$P11>$O11),"Check: pairings exceed capacity. ","")&IF(AND($BH11="Everyone",NOT(AND($BD11="Yes",$BG11="Yes"))),"Check: approved to tutor children but WWCC not provided/confirmed. ","")&IF(AND($P11>0,NOT(AND(OR(LEFT($AY11,3)="Yes",LEFT($AY11,2)="NA"),OR(LEFT($AZ11,3)="Yes",LEFT($AZ11,2)="NA")))),"Matched but vetting incomplete (interview/reference). ","")&IF(COUNTIF($B$3:$B$600,$B11)>1,"Duplicate participant name. ","")) | BO11: S-N-00017 | BP11: =IFERROR(VLOOKUP(BO11,$A:$B,2,FALSE),"") | BQ11: 45831 | BS11: 1.5 | BT11: THET Moh Moh | BU11: S-O-00041 | BV11: =IFERROR(VLOOKUP(BU11,$A:$B,2,FALSE),"") | BW11: 45617 | BY11: 1 | BZ11: MCCRORIE John | CS11: =IF(LEFT($J11,3)="ERR",0,1) | CT11: =IF(LEFT($J11,3)="ADM",1,0) | CU11: =IF(OR($J11="ADM-ACT-MAT-CNE",$J11="ADM-ACT-MAT-CE",$J11="ADM-INACT-M&T"),1,0) | CV11: =IF(AND(CU11=1,ISNUMBER(M11),ISNUMBER(I11)),M11-I11,"") | CW11: =IF(ISNUMBER(I11),TODAY()-I11,"") | CX11: =IF(ISNUMBER(I11),DATE(YEAR(I11),MONTH(I11),1),"") | CY11: =IFERROR(DATEDIF(AK11,TODAY(),"y"),"") | CZ11: =IF(CY11="","",IF(CY11<28,"18-27",IF(CY11<38,"28-37",IF(CY11<48,"38-47",IF(CY11<58,"48-57",IF(CY11<68,"58-67",IF(CY11<78,"68-77","78+")))))) | DA11: =IF(AND(BQ11<>"",BR11=""),N(BS11),0)+IF(AND(BW11<>"",BX11=""),N(BY11),0)+IF(AND(CC11<>"",CD11=""),N(CE11),0)+IF(AND(CI11<>"",CJ11=""),N(CK11),0)+IF(AND(CO11<>"",CP11=""),N(CQ11),0) | DB11: =ROUND(IF(BQ11<>"",N(BS11)*MAX(0,((IF(BR11="",TODAY(),BR11))-BQ11)/7),0)+IF(BW11<>"",N(BY11)*MAX(0,((IF(BX11="",TODAY(),BX11))-BW11)/7),0)+IF(CC11<>"",N(CE11)*MAX(0,((IF(CD11="",TODAY(),CD11))-CC11)/7),0)+IF(CI11<>"",N(CK11)*MAX(0,((IF(CJ11="",TODAY(),CJ11))-CI11)/7),0)+IF(CO11<>"",N(CQ11)*MAX(0,((IF(CP11="",TODAY(),CP11))-CO11)/7),0),1) | DC11: =IF(OR(TRIM(X11)="",TRIM(X11)="NA;",TRIM(X11)="NA"),0,1) | DD11: =IF(OR(TRIM(Y11)="",TRIM(Y11)="NA;",TRIM(Y11)="NA"),0,1) | DE11: =IF(OR(TRIM(Z11)="",TRIM(Z11)="NA;",TRIM(Z11)="NA"),0,1) | DF11: =IF(OR(TRIM(AA11)="",TRIM(AA11)="NA;",TRIM(AA11)="NA"),0,1) | DG11: =IF(OR(TRIM(AB11)="",TRIM(AB11)="NA;",TRIM(AB11)="NA"),0,1) | DH11: =IF(OR(TRIM(AC11)="",TRIM(AC11)="NA;",TRIM(AC11)="NA"),0,1) | DI11: =IF(OR(TRIM(AD11)="",TRIM(AD11)="NA;",TRIM(AD11)="NA"),0,1) | DJ11: =TRIM(IF(DC11=1,"Mon ","")&IF(DD11=1,"Tue ","")&IF(DE11=1,"Wed ","")&IF(DF11=1,"Thu ","")&IF(DG11=1,"Fri ","")&IF(DH11=1,"Sat ","")&IF(DI11=1,"Sun ",""))
A12: T-O-00010 | B12: Ahmad Taylor | C12: ahmad.taylor10@example.com | D12: +61 433 769 253 | E12: Pedro Slaytor | F12: +61 498 598 968 | G12: Caseworker | H12: Tutor | I12: 45367 | J12: ADM-ACT-MAT-CNE | K12: =IFERROR(VLOOKUP(J12,'(A) Introduction'!$B$35:$C$45,2,FALSE),"") | L12: No | O12: 3 | P12: =IF($H12="Tutor",((BQ12<>"")*(BR12=""))+((BW12<>"")*(BX12=""))+((CC12<>"")*(CD12=""))+((CI12<>"")*(CJ12=""))+((CO12<>"")*(CP12="")),SUMPRODUCT(--($BO$3:$BO$202=$A12),--($BR$3:$BR$202=""))+SUMPRODUCT(--($BU$3:$BU$202=$A12),--($BX$3:$BX$202=""))+SUMPRODUCT(--($CA$3:$CA$202=$A12),--($CD$3:$CD$202=""))+SUMPRODUCT(--($CG$3:$CG$202=$A12),--($CJ$3:$CJ$202=""))+SUMPRODUCT(--($CM$3:$CM$202=$A12),--($CP$3:$CP$202=""))) | Q12: =IF($H12="Tutor",(BQ12<>"")+(BW12<>"")+(CC12<>"")+(CI12<>"")+(CO12<>""),SUMPRODUCT(--($BO$3:$BO$202=$A12))+SUMPRODUCT(--($BU$3:$BU$202=$A12))+SUMPRODUCT(--($CA$3:$CA$202=$A12))+SUMPRODUCT(--($CG$3:$CG$202=$A12))+SUMPRODUCT(--($CM$3:$CM$202=$A12))) | R12: =IF($H12="Tutor",TRIM(IF(AND(BQ12<>"",BR12=""),BP12&"; ","")&IF(AND(BW12<>"",BX12=""),BV12&"; ","")&IF(AND(CC12<>"",CD12=""),CB12&"; ","")&IF(AND(CI12<>"",CJ12=""),CH12&"; ","")&IF(AND(CO12<>"",CP12=""),CN12&"; ","")),IFERROR(INDEX($A$3:$B$202,(SUMPRODUCT(($BO$3:$BO$202=$A12)*($BR$3:$BR$202="")*ROW($BO$3:$BO$202))+SUMPRODUCT(($BU$3:$BU$202=$A12)*($BX$3:$BX$202="")*ROW($BU$3:$BU$202))+SUMPRODUCT(($CA$3:$CA$202=$A12)*($CD$3:$CD$202="")*ROW($CA$3:$CA$202))+SUMPRODUCT(($CG$3:$CG$202=$A12)*($CJ$3:$CJ$202="")*ROW($CG$3:$CG$202))+SUMPRODUCT(($CM$3:$CM$202=$A12)*($CP$3:$CP$202="")*ROW($CM$3:$CM$202)))-2,2),"")) | S12: NA | V12: 45721 | W12: AEDT (UTC+11) | X12: 12pm-3pm; | Y12: 3pm-6pm; | Z12: 6pm-9pm; | AA12: 6pm-9pm; | AB12: 3pm-6pm; | AC12: 12pm-3pm; | AD12: 3pm-6pm; | AE12: In-Person | AF12: NA - Tutor | AG12: Australia | AH12: New South Wales | AI12: Blacktown | AJ12: 2148 | AK12: 27885 | AL12: Other | AM12: NA | AN12: NA - Tutor | AO12: Low | AP12: Australia; Egypt | AQ12: NA | AR12: English (C2) | AS12: Christian (Catholic) | AT12: Trades & Construction | AU12: Student | AV12: NA - Tutor | AW12: Cooking; Reading; Music | AX12: NA - Tutor | AY12: NA - RELT Member Verified | AZ12: NA - Partner Organisation Verified | BA12: Layla King | BB12: Friend | BC12: viktor.hadaya510@example.com | BD12: Yes | BE12: WWC3733691V | BF12: 46847 | BG12: No | BH12: Adults Only | BI12: Settlement Services International | BJ12: AGARWAL Akanksha | BK12: HERVIR Oliver | BL12: Synthetic test record. | BN12: =TRIM(IF(AND($H12="Student",$J12="ADM-ACT-MAT-CNE"),"Invalid: Student cannot be CNE. ","")&IF(AND($H12="Student",ISNUMBER($O12)),"Check: capacity set for a Student. ","")&IF(AND(LEFT($J12,11)="ADM-ACT-MAT",$P12=0),"Check: matched status but 0 active pairings. ","")&IF(AND($H12="Tutor",ISNUMBER($O12),$P12>$O12),"Check: pairings exceed capacity. ","")&IF(AND($BH12="Everyone",NOT(AND($BD12="Yes",$BG12="Yes"))),"Check: approved to tutor children but WWCC not provided/confirmed. ","")&IF(AND($P12>0,NOT(AND(OR(LEFT($AY12,3)="Yes",LEFT($AY12,2)="NA"),OR(LEFT($AZ12,3)="Yes",LEFT($AZ12,2)="NA")))),"Matched but vetting incomplete (interview/reference). ","")&IF(COUNTIF($B$3:$B$600,$B12)>1,"Duplicate participant name. ","")) | BO12: S-N-00049 | BP12: =IFERROR(VLOOKUP(BO12,$A:$B,2,FALSE),"") | BQ12: 46098 | BS12: 2 | BT12: SINGH Veera | CS12: =IF(LEFT($J12,3)="ERR",0,1) | CT12: =IF(LEFT($J12,3)="ADM",1,0) | CU12: =IF(OR($J12="ADM-ACT-MAT-CNE",$J12="ADM-ACT-MAT-CE",$J12="ADM-INACT-M&T"),1,0) | CV12: =IF(AND(CU12=1,ISNUMBER(M12),ISNUMBER(I12)),M12-I12,"") | CW12: =IF(ISNUMBER(I12),TODAY()-I12,"") | CX12: =IF(ISNUMBER(I12),DATE(YEAR(I12),MONTH(I12),1),"") | CY12: =IFERROR(DATEDIF(AK12,TODAY(),"y"),"") | CZ12: =IF(CY12="","",IF(CY12<28,"18-27",IF(CY12<38,"28-37",IF(CY12<48,"38-47",IF(CY12<58,"48-57",IF(CY12<68,"58-67",IF(CY12<78,"68-77","78+")))))) | DA12: =IF(AND(BQ12<>"",BR12=""),N(BS12),0)+IF(AND(BW12<>"",BX12=""),N(BY12),0)+IF(AND(CC12<>"",CD12=""),N(CE12),0)+IF(AND(CI12<>"",CJ12=""),N(CK12),0)+IF(AND(CO12<>"",CP12=""),N(CQ12),0) | DB12: =ROUND(IF(BQ12<>"",N(BS12)*MAX(0,((IF(BR12="",TODAY(),BR12))-BQ12)/7),0)+IF(BW12<>"",N(BY12)*MAX(0,((IF(BX12="",TODAY(),BX12))-BW12)/7),0)+IF(CC12<>"",N(CE12)*MAX(0,((IF(CD12="",TODAY(),CD12))-CC12)/7),0)+IF(CI12<>"",N(CK12)*MAX(0,((IF(CJ12="",TODAY(),CJ12))-CI12)/7),0)+IF(CO12<>"",N(CQ12)*MAX(0,((IF(CP12="",TODAY(),CP12))-CO12)/7),0),1) | DC12: =IF(OR(TRIM(X12)="",TRIM(X12)="NA;",TRIM(X12)="NA"),0,1) | DD12: =IF(OR(TRIM(Y12)="",TRIM(Y12)="NA;",TRIM(Y12)="NA"),0,1) | DE12: =IF(OR(TRIM(Z12)="",TRIM(Z12)="NA;",TRIM(Z12)="NA"),0,1) | DF12: =IF(OR(TRIM(AA12)="",TRIM(AA12)="NA;",TRIM(AA12)="NA"),0,1) | DG12: =IF(OR(TRIM(AB12)="",TRIM(AB12)="NA;",TRIM(AB12)="NA"),0,1) | DH12: =IF(OR(TRIM(AC12)="",TRIM(AC12)="NA;",TRIM(AC12)="NA"),0,1) | DI12: =IF(OR(TRIM(AD12)="",TRIM(AD12)="NA;",TRIM(AD12)="NA"),0,1) | DJ12: =TRIM(IF(DC12=1,"Mon ","")&IF(DD12=1,"Tue ","")&IF(DE12=1,"Wed ","")&IF(DF12=1,"Thu ","")&IF(DG12=1,"Fri ","")&IF(DH12=1,"Sat ","")&IF(DI12=1,"Sun ",""))
A13: T-O-00011 | B13: Sara Bourne | C13: sara.bourne11@example.com | D13: +61 453 551 765 | E13: Nour Ali | F13: +61 459 186 051 | G13: Sibling | H13: Tutor | I13: 45369 | J13: ADM-ACT-MAT-CNE | K13: =IFERROR(VLOOKUP(J13,'(A) Introduction'!$B$35:$C$45,2,FALSE),"") | L13: No | O13: 3 | P13: =IF($H13="Tutor",((BQ13<>"")*(BR13=""))+((BW13<>"")*(BX13=""))+((CC13<>"")*(CD13=""))+((CI13<>"")*(CJ13=""))+((CO13<>"")*(CP13="")),SUMPRODUCT(--($BO$3:$BO$202=$A13),--($BR$3:$BR$202=""))+SUMPRODUCT(--($BU$3:$BU$202=$A13),--($BX$3:$BX$202=""))+SUMPRODUCT(--($CA$3:$CA$202=$A13),--($CD$3:$CD$202=""))+SUMPRODUCT(--($CG$3:$CG$202=$A13),--($CJ$3:$CJ$202=""))+SUMPRODUCT(--($CM$3:$CM$202=$A13),--($CP$3:$CP$202=""))) | Q13: =IF($H13="Tutor",(BQ13<>"")+(BW13<>"")+(CC13<>"")+(CI13<>"")+(CO13<>""),SUMPRODUCT(--($BO$3:$BO$202=$A13))+SUMPRODUCT(--($BU$3:$BU$202=$A13))+SUMPRODUCT(--($CA$3:$CA$202=$A13))+SUMPRODUCT(--($CG$3:$CG$202=$A13))+SUMPRODUCT(--($CM$3:$CM$202=$A13))) | R13: =IF($H13="Tutor",TRIM(IF(AND(BQ13<>"",BR13=""),BP13&"; ","")&IF(AND(BW13<>"",BX13=""),BV13&"; ","")&IF(AND(CC13<>"",CD13=""),CB13&"; ","")&IF(AND(CI13<>"",CJ13=""),CH13&"; ","")&IF(AND(CO13<>"",CP13=""),CN13&"; ","")),IFERROR(INDEX($A$3:$B$202,(SUMPRODUCT(($BO$3:$BO$202=$A13)*($BR$3:$BR$202="")*ROW($BO$3:$BO$202))+SUMPRODUCT(($BU$3:$BU$202=$A13)*($BX$3:$BX$202="")*ROW($BU$3:$BU$202))+SUMPRODUCT(($CA$3:$CA$202=$A13)*($CD$3:$CD$202="")*ROW($CA$3:$CA$202))+SUMPRODUCT(($CG$3:$CG$202=$A13)*($CJ$3:$CJ$202="")*ROW($CG$3:$CG$202))+SUMPRODUCT(($CM$3:$CM$202=$A13)*($CP$3:$CP$202="")*ROW($CM$3:$CM$202)))-2,2),"")) | S13: NA | V13: 46039 | W13: AEST (UTC+10) | X13: 6pm-9pm; | Y13: 12pm-3pm; | Z13: 3pm-6pm; | AA13: 12pm-3pm;6pm-9pm; | AB13: 6pm-9pm; | AC13: NA; | AD13: 12pm-3pm;6pm-9pm; | AE13: In-Person | AF13: NA - Tutor | AG13: Australia | AH13: New South Wales | AI13: Marrickville | AJ13: 2204 | AK13: 33605 | AL13: Other | AM13: NA | AN13: NA - Tutor | AO13: Outstanding | AP13: United Kingdom | AQ13: NA | AR13: English (C2) | AS13: Christian (Catholic) | AT13: Law & Legal Services | AU13: Nurse | AV13: NA - Tutor | AW13: Football; Cooking; Family | AX13: NA - Tutor | AY13: No | AZ13: Yes | BA13: Tariq Marks | BB13: Manager | BC13: rania.marks511@example.com | BD13: Yes | BE13: WWC5780430E | BF13: 46269 | BG13: No | BH13: Adults Only | BI13: AMES Australia | BJ13: CROCK Mary | BK13: THET Moh Moh | BL13: Synthetic test record. | BN13: =TRIM(IF(AND($H13="Student",$J13="ADM-ACT-MAT-CNE"),"Invalid: Student cannot be CNE. ","")&IF(AND($H13="Student",ISNUMBER($O13)),"Check: capacity set for a Student. ","")&IF(AND(LEFT($J13,11)="ADM-ACT-MAT",$P13=0),"Check: matched status but 0 active pairings. ","")&IF(AND($H13="Tutor",ISNUMBER($O13),$P13>$O13),"Check: pairings exceed capacity. ","")&IF(AND($BH13="Everyone",NOT(AND($BD13="Yes",$BG13="Yes"))),"Check: approved to tutor children but WWCC not provided/confirmed. ","")&IF(AND($P13>0,NOT(AND(OR(LEFT($AY13,3)="Yes",LEFT($AY13,2)="NA"),OR(LEFT($AZ13,3)="Yes",LEFT($AZ13,2)="NA")))),"Matched but vetting incomplete (interview/reference). ","")&IF(COUNTIF($B$3:$B$600,$B13)>1,"Duplicate participant name. ","")) | BO13: S-N-00048 | BP13: =IFERROR(VLOOKUP(BO13,$A:$B,2,FALSE),"") | BQ13: 46003 | BS13: 1 | BT13: AGARWAL Akanksha | BU13: S-O-00048 | BV13: =IFERROR(VLOOKUP(BU13,$A:$B,2,FALSE),"") | BW13: 45694 | BX13: 45864 | BY13: 1.5 | BZ13: KNIJNIK Marina | CS13: =IF(LEFT($J13,3)="ERR",0,1) | CT13: =IF(LEFT($J13,3)="ADM",1,0) | CU13: =IF(OR($J13="ADM-ACT-MAT-CNE",$J13="ADM-ACT-MAT-CE",$J13="ADM-INACT-M&T"),1,0) | CV13: =IF(AND(CU13=1,ISNUMBER(M13),ISNUMBER(I13)),M13-I13,"") | CW13: =IF(ISNUMBER(I13),TODAY()-I13,"") | CX13: =IF(ISNUMBER(I13),DATE(YEAR(I13),MONTH(I13),1),"") | CY13: =IFERROR(DATEDIF(AK13,TODAY(),"y"),"") | CZ13: =IF(CY13="","",IF(CY13<28,"18-27",IF(CY13<38,"28-37",IF(CY13<48,"38-47",IF(CY13<58,"48-57",IF(CY13<68,"58-67",IF(CY13<78,"68-77","78+")))))) | DA13: =IF(AND(BQ13<>"",BR13=""),N(BS13),0)+IF(AND(BW13<>"",BX13=""),N(BY13),0)+IF(AND(CC13<>"",CD13=""),N(CE13),0)+IF(AND(CI13<>"",CJ13=""),N(CK13),0)+IF(AND(CO13<>"",CP13=""),N(CQ13),0) | DB13: =ROUND(IF(BQ13<>"",N(BS13)*MAX(0,((IF(BR13="",TODAY(),BR13))-BQ13)/7),0)+IF(BW13<>"",N(BY13)*MAX(0,((IF(BX13="",TODAY(),BX13))-BW13)/7),0)+IF(CC13<>"",N(CE13)*MAX(0,((IF(CD13="",TODAY(),CD13))-CC13)/7),0)+IF(CI13<>"",N(CK13)*MAX(0,((IF(CJ13="",TODAY(),CJ13))-CI13)/7),0)+IF(CO13<>"",N(CQ13)*MAX(0,((IF(CP13="",TODAY(),CP13))-CO13)/7),0),1) | DC13: =IF(OR(TRIM(X13)="",TRIM(X13)="NA;",TRIM(X13)="NA"),0,1) | DD13: =IF(OR(TRIM(Y13)="",TRIM(Y13)="NA;",TRIM(Y13)="NA"),0,1) | DE13: =IF(OR(TRIM(Z13)="",TRIM(Z13)="NA;",TRIM(Z13)="NA"),0,1) | DF13: =IF(OR(TRIM(AA13)="",TRIM(AA13)="NA;",TRIM(AA13)="NA"),0,1) | DG13: =IF(OR(TRIM(AB13)="",TRIM(AB13)="NA;",TRIM(AB13)="NA"),0,1) | DH13: =IF(OR(TRIM(AC13)="",TRIM(AC13)="NA;",TRIM(AC13)="NA"),0,1) | DI13: =IF(OR(TRIM(AD13)="",TRIM(AD13)="NA;",TRIM(AD13)="NA"),0,1) | DJ13: =TRIM(IF(DC13=1,"Mon ","")&IF(DD13=1,"Tue ","")&IF(DE13=1,"Wed ","")&IF(DF13=1,"Thu ","")&IF(DG13=1,"Fri ","")&IF(DH13=1,"Sat ","")&IF(DI13=1,"Sun ",""))
